<mujoco>
  <default>
    <joint armature="1" damping="1" limited="true"/>
    <geom condim="3" density="5.0" friction="1 0.5 0.5" margin="0.01" rgba="0.8 0.6 0.4 1"/>
  </default>
  <worldbody>
    <light diffuse=".5 .5 .5" pos="0 0 3" dir="0 0 -1" />
    <body pos="0 0 0" name="">
      <geom type="plane" size="5 5 1.110223E-16" euler="0 0 0" rgba="0 255 0 1" name="" />
    </body>
    <body pos="0.009118199 -4.860559 0.4894152" name="">
      <geom type="box" size="5 0.25 0.5" euler="0 0 0" rgba="0 .9 0 1" name="" />
    </body>
    <body pos="-0.001238585 4.898753 0.467675" name="">
      <geom type="box" size="5 0.25 0.5" euler="0 0 0" rgba="0 .9 0 1" name="" />
    </body>
    <body pos="4.761338 -0.08965623 0.4880085" name="">
      <geom type="box" size="0.25 5 0.5" euler="0 0 0" rgba="0 .9 0 1" name="" />
    </body>
    <body pos="-4.727 0.1185943 0.4880471" name="">
      <geom type="box" size="0.25 5 0.5" euler="0 0 0" rgba="0 .9 0 1" name="" />
    </body>
    <body pos="-4.280405 -0.4097991 0.5016704" name="goal">
      <geom type="box" size="0.25 1.5 0.5" euler="0 0 0" rgba="255 0 0 1" name="goal_geom0" />
    </body>
    <body pos="2.020049 2.728031 0.9" name="red_1">
      <camera name="red_1_track" mode="trackcom" pos="0 -3 0.3" xyaxes="1 0 0 0 0 1"/>
      <geom name="red_1_torso_geom" pos="0 0 0" size="0.25" type="sphere"/>
      <joint armature="0" damping="0" limited="false" margin="0.01" name="red_1_root" pos="0 0 0" type="free"/>
      <body name="red_1_front_left_leg" pos="0 0 0">
        <geom fromto="0.0 0.0 0.0 0.2 0.2 0.0" name="red_1_aux_1_geom" size="0.08" type="capsule"/>
        <body name="red_1_aux_1" pos="0.2 0.2 0">
          <joint axis="0 0 1" name="red_1_hip_1" pos="0.0 0.0 0.0" range="-30 30" type="hinge"/>
          <geom fromto="0.0 0.0 0.0 0.2 0.2 0.0" name="red_1_left_leg_geom" size="0.08" type="capsule"/>
          <body pos="0.2 0.2 0">
            <joint axis="-1 1 0" name="red_1_ankle_1" pos="0.0 0.0 0.0" range="30 70" type="hinge"/>
            <geom fromto="0.0 0.0 0.0 0.4 0.4 0.0" name="red_1_left_ankle_geom" size="0.08" type="capsule"/>
          </body>
        </body>
      </body>
      <body name="red_1_front_right_leg" pos="0 0 0">
        <geom fromto="0.0 0.0 0.0 -0.2 0.2 0.0" name="red_1_aux_2_geom" size="0.08" type="capsule"/>
        <body name="red_1_aux_2" pos="-0.2 0.2 0">
          <joint axis="0 0 1" name="red_1_hip_2" pos="0.0 0.0 0.0" range="-30 30" type="hinge"/>
          <geom fromto="0.0 0.0 0.0 -0.2 0.2 0.0" name="red_1_right_leg_geom" size="0.08" type="capsule"/>
          <body pos="-0.2 0.2 0">
            <joint axis="1 1 0" name="red_1_ankle_2" pos="0.0 0.0 0.0" range="-70 -30" type="hinge"/>
            <geom fromto="0.0 0.0 0.0 -0.4 0.4 0.0" name="red_1_right_ankle_geom" size="0.08" type="capsule"/>
          </body>
        </body>
      </body>
      <body name="red_1_back_leg" pos="0 0 0">
        <geom fromto="0.0 0.0 0.0 -0.2 -0.2 0.0" name="red_1_aux_3_geom" size="0.08" type="capsule"/>
        <body name="red_1_aux_3" pos="-0.2 -0.2 0">
          <joint axis="0 0 1" name="red_1_hip_3" pos="0.0 0.0 0.0" range="-30 30" type="hinge"/>
          <geom fromto="0.0 0.0 0.0 -0.2 -0.2 0.0" name="red_1_back_leg_geom" size="0.08" type="capsule"/>
          <body pos="-0.2 -0.2 0">
            <joint axis="-1 1 0" name="red_1_ankle_3" pos="0.0 0.0 0.0" range="-70 -30" type="hinge"/>
            <geom fromto="0.0 0.0 0.0 -0.4 -0.4 0.0" name="red_1_third_ankle_geom" size="0.08" type="capsule"/>
          </body>
        </body>
      </body>
      <body name="red_1_right_back_leg" pos="0 0 0">
        <geom fromto="0.0 0.0 0.0 0.2 -0.2 0.0" name="red_1_aux_4_geom" size="0.08" type="capsule"/>
        <body name="red_1_aux_4" pos="0.2 -0.2 0">
          <joint axis="0 0 1" name="red_1_hip_4" pos="0.0 0.0 0.0" range="-30 30" type="hinge"/>
          <geom fromto="0.0 0.0 0.0 0.2 -0.2 0.0" name="red_1_rightback_leg_geom" size="0.08" type="capsule"/>
          <body pos="0.2 -0.2 0">
            <joint axis="1 1 0" name="red_1_ankle_4" pos="0.0 0.0 0.0" range="30 70" type="hinge"/>
            <geom fromto="0.0 0.0 0.0 0.4 -0.4 0.0" name="red_1_fourth_ankle_geom" size="0.08" type="capsule"/>
          </body>
        </body>
      </body>
    </body>
    <body pos="-0.183617 -1.732173 0.601779" name="ball">
      <joint type="free"/>
      <inertial mass="0.15" diaginertia="0.1 0.1 0.1" pos="0 0 0"/>
      <geom type="sphere" size="0.4 0.4 0.4" euler="0 0 0" rgba="0 .9 0 1" name="ball_geom0" />
    </body>
  </worldbody>
  <sensor />
  <actuator>
    <motor ctrllimited="true" ctrlrange="-1.0 1.0" joint="red_1_hip_4" gear="150" name="red_1_hip_4_motor"/>
    <motor ctrllimited="true" ctrlrange="-1.0 1.0" joint="red_1_ankle_4" gear="150" name="red_1_ankle_4_motor"/>
    <motor ctrllimited="true" ctrlrange="-1.0 1.0" joint="red_1_hip_1" gear="150" name="red_1_hip_1_motor"/>
    <motor ctrllimited="true" ctrlrange="-1.0 1.0" joint="red_1_ankle_1" gear="150" name="red_1_ankle_1_motor"/>
    <motor ctrllimited="true" ctrlrange="-1.0 1.0" joint="red_1_hip_2" gear="150" name="red_1_hip_2_motor"/>
    <motor ctrllimited="true" ctrlrange="-1.0 1.0" joint="red_1_ankle_2" gear="150" name="red_1_ankle_2_motor"/>
    <motor ctrllimited="true" ctrlrange="-1.0 1.0" joint="red_1_hip_3" gear="150" name="red_1_hip_3_motor"/>
    <motor ctrllimited="true" ctrlrange="-1.0 1.0" joint="red_1_ankle_3" gear="150" name="red_1_ankle_3_motor"/>
  </actuator>
</mujoco>
